<?xml version="1.0" ?>

<robot name="mouse" xmlns:xacro="https://www.ros.org/wiki/xacro" >

    <!--============================ Adjust bot params here =========================-->
    <!-- diameter of wheel default = 0.010-->
    <xacro:property name="D" value="0.010"/>
    <!-- width of wheel default = 0.0025-->
    <xacro:property name="W" value="0.0025"/>
    <!-- side length of base default = 0.02-->
    <xacro:property name="S" value="0.020"/> 
    <!-- diameter of lidar default = 0.01-->
    <xacro:property name="L" value="0.010"/>
    <!-- height of lidar from base surface -->
    <xacro:property name="H" value="0.007"/>
    <!-- thickness of base default = 0.004-->
    <xacro:property name="T" value="0.004"/>
    <!-- height of wheel axes from base TF frame -->
    <xacro:property name="E" value="0.000"/>

    <!-- mass of the base -->
    <xacro:property name="M" value="0.4"/>
    <!-- mass of one wheel -->
    <xacro:property name="m" value="0.05"/>

    <!-- ============================================================================ -->

    <material name="black">
    <color rgba="0.0 0.0 0.0 1.0"/>
    </material>
    <material name="blue">
    <color rgba="0.203125 0.23828125 0.28515625 1.0"/>
    </material>
    <material name="green">
    <color rgba="0.0 0.8 0.0 1.0"/>
    </material>
    <material name="grey">
    <color rgba="0.2 0.2 0.2 1.0"/>
    </material>
    <material name="orange">
    <color rgba="1.0 0.423529411765 0.0392156862745 1.0"/>
    </material>
    <material name="brown">
    <color rgba="0.870588235294 0.811764705882 0.764705882353 1.0"/>
    </material>
    <material name="red">
    <color rgba="0.80078125 0.12890625 0.1328125 1.0"/>
    </material>
    <material name="white">
        <color rgba="1.0 1.0 1.0 1.0"/>
    </material>  
    
    <xacro:macro name="wheel" params="name mass radius width">
        <link name="${name}">
            <inertial>
                <mass value="${mass}"/>
                <inertia ixx="${mass*(3*radius*radius + width*width)/12}" 
                        ixy="0.0" 
                        ixz="0.0" 
                        iyy="${mass*(3*radius*radius + width*width)/12}" 
                        iyz="0.0" 
                        izz="${mass*radius*radius/2}"/>
            </inertial>
            <visual>
                <geometry>
                    <cylinder radius="${radius}" length="${width}"/>
                </geometry>
                <material name="black">
                    <color rgba="0.0 0.0 0.0 1.0"/>
                </material>
            </visual>
            <surface>
                <friction>
                    <ode>
                        <mu>0.0</mu>
                        <mu2>0.000001</mu2>
                    </ode>
                </friction>
            </surface>
            <collision>
                <geometry>
                    <cylinder radius="${radius}" length="${width}"/>
                </geometry>
            </collision>
        </link>
        <gazebo reference="${name}">
            <material>Gazebo/Black</material>
            <kp>100000.0</kp>
            <kd>100000.0</kd>
            <mu1>0.001</mu1>
            <mu2>1.0</mu2>
            <fdir1>0 0 1</fdir1>
        </gazebo>
    </xacro:macro>

    <xacro:macro name="wheel_joint" params="name parent child xyz rpy">
        <joint name="${name}" type="continuous">
            <parent link="${parent}"/>
            <child link="${child}"/>
            <origin xyz="${xyz}" rpy="${rpy}"/>
            <axis xyz="0 0 1" rpy="0 0 0"/>
            <limit effort="1000" velocity="1000"/>
            <joint_properties damping="1.0" friction="1.0" />
        </joint>
    </xacro:macro>

    <!-- ================================ chassis ================================= -->
    <link name="micromouse_frame"/>
    <joint name="micromouse_frame_to_main_body" type="fixed">
        <parent link="micromouse_frame"/>
        <child link="main_body"/>
    </joint>

    <link name="main_body">
        <inertial>
            <mass value="${M}"/>
            <inertia ixx="${M*(S*S + T*T)/12}" ixy="0.0" ixz="0.0" iyy="${M*(S*S + T*T)/12}" iyz="0.0" izz="${M*S*S/6}"/>
        </inertial>
        <visual>
            <geometry>
                <box size="${S} ${S} ${T}"/>
            </geometry>
            <material name="white">
                <color rgba="1.0 1.0 1.0 1.0"/>
            </material> 
        </visual>
        <visual>
            <origin xyz="0.0 0.0 ${H/2+T/2}"/>
            <geometry>
                <cylinder radius="${L/2}" length="${H}"/>
            </geometry>
            <material name="white">
                <color rgba="1.0 1.0 1.0 1.0"/>
            </material>
        </visual>
        <collision>
            <geometry>
                <box size="${S} ${S} ${T}"/>
            </geometry>
        </collision>
    </link>

    <gazebo reference="main_body">
        <material>Gazebo/Blue</material>
    </gazebo>

    <!-- ======================================= wheels ======================================== -->
    <xacro:wheel name="w1" mass="${m}" radius="${D/2}" width="${W}"/>
    <xacro:wheel name="w2" mass="${m}" radius="${D/2}" width="${W}"/>
    <xacro:wheel name="w3" mass="${m}" radius="${D/2}" width="${W}"/>
    <xacro:wheel name="w4" mass="${m}" radius="${D/2}" width="${W}"/>

    <xacro:wheel_joint name="j1" parent="main_body" child="w1" xyz="   ${S/2 + W/2}               0 ${E}" rpy="0 1.57 3.14"/>
    <xacro:wheel_joint name="j2" parent="main_body" child="w2" xyz="              0    ${S/2 + W/2} ${E}" rpy="0 1.57 1.57"/>
    <xacro:wheel_joint name="j3" parent="main_body" child="w3" xyz="${-(S/2 + W/2)}               0 ${E}" rpy="0 1.57 3.14"/>
    <xacro:wheel_joint name="j4" parent="main_body" child="w4" xyz="              0 ${-(S/2 + W/2)} ${E}" rpy="0 1.57 1.57"/>

    <!-- ================================== differential drive plugins ===================================== -->

    <gazebo>
        <!-- X direction -->
        <plugin filename="libgazebo_ros_diff_drive.so" name="differential_drive_controller">
        <alwaysOn>true</alwaysOn>
        <updateRate>40</updateRate>
        <leftJoint>j2</leftJoint>
        <rightJoint>j4</rightJoint>
        <wheelSeparation>${S+W}</wheelSeparation>
        <wheelDiameter>${D}</wheelDiameter>
        <torque>5</torque>
        <commandTopic>cmd_vel_x</commandTopic>
        <odometryTopic>odom</odometryTopic>
        <odometryFrame>odom</odometryFrame>
        <robotBaseFrame>micromouse_frame</robotBaseFrame>

        <!-- some extra stuff to get rid of the warnings -->
        <rosDebugLevel>na</rosDebugLevel>
        <publishWheelTF>false</publishWheelTF>
        <publishOdomTF>true</publishOdomTF>
        <publishWheelJointState>false</publishWheelJointState>
        <wheelAcceleration>0</wheelAcceleration>
        <wheelTorque>5</wheelTorque>
        <!-- <odometrySource>1</odometrySource> -->
        <publishTf>1</publishTf>
        </plugin>

        <!-- Y direction -->
        <plugin filename="libgazebo_ros_diff_drive.so" name="differential_drive_controller">
        <alwaysOn>true</alwaysOn>
        <updateRate>40</updateRate>
        <leftJoint>j3</leftJoint>
        <rightJoint>j1</rightJoint>
        <wheelSeparation>${S+W}</wheelSeparation>
        <wheelDiameter>${D}</wheelDiameter>
        <torque>5</torque>
        <commandTopic>cmd_vel_y</commandTopic>
        <odometryTopic>odom</odometryTopic>
        <odometryFrame>odom</odometryFrame>
        <robotBaseFrame>micromouse_frame</robotBaseFrame>

        <!-- some extra stuff to get rid of the warnings -->
        <rosDebugLevel>na</rosDebugLevel>
        <publishWheelTF>false</publishWheelTF>
        <publishOdomTF>true</publishOdomTF>
        <publishWheelJointState>false</publishWheelJointState>
        <wheelAcceleration>0</wheelAcceleration>
        <wheelTorque>5</wheelTorque>
        <!-- <odometrySource>1</odometrySource> -->
        <publishTf>1</publishTf>
        </plugin>
    </gazebo>

<!-- ======================================== everything lidar ===================================== -->

    <link name="lidar_frame"/>
    <joint name="micromouse_frame_to_lidar" type="fixed">
        <parent link="micromouse_frame"/>
        <child link="lidar_frame"/>
        <origin xyz="0.0 0.0 ${H+T/2+0.001}"/>
    </joint>

    <gazebo reference="lidar_frame">
        <sensor type="ray" name="head_hokuyo_sensor">
            <pose>0 0 0 0 0 0</pose>
            <visualize>false</visualize>
            <update_rate>40</update_rate>
            <ray>
                <scan>
                    <horizontal>
                        <samples>360</samples>
                        <resolution>1</resolution>
                        <!-- default = -3.14 -->
                        <min_angle>-3.14</min_angle>
                        <!-- default = 3.14 -->
                        <max_angle>3.14</max_angle>
                    </horizontal>
                </scan>
                <range>
                    <!-- default = 0.005 -->
                    <min>0.005</min>
                    <max>3.0</max>
                    <resolution>0.001</resolution>
                </range>
            </ray>
            <plugin name="gazebo_ros_head_hokuyo_controller" filename="libgazebo_ros_laser.so">
                <topicName>laser/scan</topicName>
                <frameName>lidar_frame</frameName>
            </plugin>
        </sensor>
    </gazebo>
</robot>